<?xml version="1.0"?>
<robot xmlns:xacro="http://wiki.ros.org/wiki/xacro" name="twoarm">

<xacro:property name="arm" value="$(find homework2)/config/arm.yaml" />
<xacro:property name="dictionary" value="${load_yaml(arm)}" />

<xacro:property name="L1" value="${dictionary['L1']}" />
<xacro:property name="L2" value="${dictionary['L2']}" />
<xacro:property name="R1" value="${dictionary['R1']}" />
<xacro:property name="R2" value="${dictionary['R2']}" />
<xacro:property name="m" value="1" />

<link name="base_link" >
    <visual>
    <origin xyz="0 0 0" rpy="0 0 0" />
        <geometry>
            <cylinder radius="0.1" length="0.1"/>
        </geometry>
        <material name="red_mat">
            <color rgba="1 0 0 0.5" />
        </material>
    </visual>
</link>

<joint name="joint1" type="continuous">
    <axis xyz="0 0 1" />
    <origin xyz="0 0 0.05" rpy="0 0 0" />
    <parent link="base_link" />
    <child link="link1" />
</joint>

<link name="link1">
    <visual>
    <origin xyz="${L1/2} 0 0" rpy="${pi/4} ${pi/2} ${pi/4}" />
        <geometry>
            <cylinder radius="${R1}" length="${L1}"/>
        </geometry>
        <material name="green_mat">
            <color rgba="0 1 0 1" />
        </material>
        <inertial>
           <mass value="${m}"/>
           <inertia ixx="1/12*${m}*(3*${R1}**2 + ${L1}**2)" ixy="0.0" ixz="0.0" iyy="1/12*${m}*(3*${R1}**2 + ${L1}**2)" iyz="0.0" izz="1/2*${m}*${R1}**2"/>
         </inertial>
    </visual>
    <collision>
           <geometry>
             <cylinder length="${L1}" radius="${R1}"/>
           </geometry>
    </collision>
</link>

<joint name ="joint2" type="continuous">
    <axis xyz="0 0 1" />
    <origin xyz="${L1} 0 0" rpy="0 0 0" />
    <parent link="link1" />
    <child link="link2" />
</joint>

<link name="link2">
    <visual>
    <origin xyz="${L2/2} 0 0" rpy="0 ${pi/2} 0" />
        <geometry>
            <cylinder radius="${R2}" length="${L2}"/>
        </geometry>
        <material name="blue_mat">
            <color rgba="0 0 1 1" />
        </material>
        <inertial>
           <mass value="${m}"/>
           <inertia ixx="1/12*${m}*(3*${R2}**2 + ${L2}**2)" ixy="0.0" ixz="0.0" iyy="1/12*${m}*(3*${R2}**2 + ${L2}**2)" iyz="0.0" izz="1/2*${m}*${R2}**2"/>
         </inertial>
    </visual>
    <collision>
           <geometry>
             <cylinder length="${L2}" radius="${R2}"/>
           </geometry>
    </collision>
</link> 

<joint name ="joint3" type="fixed">
    <axis xyz="0 0 1" />
    <origin xyz="${L2} 0 0" rpy="0 0 0" />
    <parent link="link2" />
    <child link="link3" />
</joint>

<link name="link3">
    <visual>
    <origin xyz="${L2/2} 0 0" rpy="0 ${pi/2} 0" />
        <geometry>
            <cylinder radius="${R2}" length="0.1"/>
        </geometry>
        <material name="transparent_mat">
            <color rgba="1 1 1 0" />
        </material>
    </visual>
</link> 

</robot>

